Workbook

Sheet Patterns
A1: Date | B1: Weekdays | D1: Number | E1: Formula Parts

Sheet Sum
A1: Countries | B1: Jan | C1: Feb | D1: Mar | E1: Apr | F1: May | G1: Jun | H1: Total
A2: Usa | B2: 13 | C2: 19 | D2: 16 | E2: 16 | F2: 17 | G2: 20
A3: China | B3: 11 | C3: 20 | D3: 17 | E3: 19 | F3: 12 | G3: 16
A4: Greece | B4: 19 | C4: 15 | D4: 16 | E4: 16 | F4: 11 | G4: 20
A5: France | B5: 11 | C5: 20 | D5: 16 | E5: 10 | F5: 17 | G5: 15
A6: Total

Sheet Chart
A1: Date | B1: Jan | C1: Feb | D1: Mar | E1: Apr | F1: May | G1: Jun
A2: Revenue | B2: 13164 | C2: 9873 | D2: 35000 | E2: 30818 | F2: 26297 | G2: 18963
A3: Expense | B3: 17746 | C3: 13537 | D3: 19788 | E3: 14947 | F3: 25808 | G3: 49317
A4: P&L | B4: 40317 | C4: 38992 | D4: 23041 | E4: 21727 | F4: 33090 | G4: 6385

Sheet Filter
A1: Shipped Date | B1: Ship to | C1: Payment Type | D1: Unit Price | E1: Quantity | F1: Revenue | G1: Shipping Fee
A2: 44590 | B2: Jon Fist | C2: Check | D2: 12 | E2: 7 | F2: 11 | G2: 19
A3: 44590 | B3: Jon Fist | C3: Check | D3: 19 | E3: 9 | F3: 19 | G3: 24
A4: 44567 | B4: Mary Lesly | C4: Credit Card | D4: 12 | E4: 18 | F4: 19 | G4: 13
A5: 44567 | B5: Mary Lesly | C5: Credit Card | D5: 24 | E5: 21 | F5: 14 | G5: 24
A6: 44567 | B6: Mary Lesly | C6: Cash | D6: 9 | E6: 15 | F6: 18 | G6: 14
A7: 44575 | B7: Peter Edwi | C7: Credit Card | D7: 24 | E7: 13 | F7: 12 | G7: 15
A8: 44575 | B8: Peter Edwi | C8: Cash | D8: 24 | E8: 8 | F8: 13 | G8: 14
A9: 44583 | B9: Liz Andersen | C9: Credit Card | D9: 24 | E9: 24 | F9: 12 | G9: 15
A10: 44571 | B10: Dora Pil | C10: Check | D10: 22 | E10: 14 | F10: 12 | G10: 12
A11: 44592 | B11: Andrew Kil | C11: Check | D11: 21 | E11: 10 | F11: 18 | G11: 20
A12: 44571 | B12: Dora Pil | C12: Cash | D12: 17 | E12: 17 | F12: 13 | G12: 6
A13: 44591 | B13: Vanzel Kats | C13: Credit Card | D13: 11 | E13: 14 | F13: 22 | G13: 20
... A24: 44568 | B24: Anna Bedi | C24: Check | D24: 22 | E24: 8 | F24: 9 | G24: 10

Sheet Lookup
A1: Description | B1: Score | C1: Rating | D1: Text 1 | E1: Text 2 | F1: Test
A2: Strategy | B2: 72 | C2: =VLOOKUP(B$2,Assumptions!$A$2:$B$4,2,1) -> Average | F2: =B2=MAX($B$2:$B$7) -> FALSE
A3: Advertising | B3: 85 | C3: =VLOOKUP(B3,Assumptions!$A$2:$B$4,2,1) -> Good | F3: =B3=MAX($B$2:$B$7) -> FALSE
A4: Marketing | B4: 40 | C4: =VLOOKUP(B4,Assumptions!$A$2:$B$4,2,1) -> Poor | F4: =B4=MAX($B$2:$B$7) -> FALSE
A5: Finance | B5: 88 | C5: =VLOOKUP(B5,Assumptions!$A$2:$B$4,2,1) -> Good | F5: =B5=MAX($B$2:$B$7) -> FALSE
A6: Sales | B6: 90 | C6: =VLOOKUP(B6,Assumptions!$A$2:$B$4,2,1) -> Good | F6: =B6=MAX($B$2:$B$7) -> TRUE
A7: Operations | B7: 45 | C7: =VLOOKUP(B7,Assumptions!$A$2:$B$4,2,1) -> Poor | F7: =B7=MAX($B$2:$B$7) -> FALSE

Sheet Assumptions
A1: Score | B1: Rating | C1: Rated
A2: 0 | B2: Poor | C2: -1
A3: 50 | B3: Average | C3: 0
A4: 80 | B4: Good | C4: 1

Sheet Pivots
A3: Row Labels | B3: Sum of Revenue
A4: Category1 | B4: 7250.14
A5: Category2 | B5: 5791.88
A6: Category3 | B6: 7548.18
A7: Category4 | B7: 4493.73
A8: Category5 | B8: 3810.83
A9: Grand Total | B9: 28894.76
A12: Row Labels | B12: Sum of Quantity
A13: China | B13: 530
A14: France | B14: 459
A15: Germany | B15: 564
A16: Greece | B16: 547
A17: Hong Kong | B17: 336
A18: Japan | B18: 251
A19: USA | B19: 620
A20: Grand Total | B20: 3307
A23: Row Labels | B23: Sum of Unit Cost
A24: Direct Sales | B24: 499.63
A25: Online Sales | B25: 371.4
A26: Wholesales | B26: 297.11
A27: Grand Total | B27: 1168.14
A30: Row Labels | B30: Sum of Selling Price
A31: 2021
A32: Jan | B32: 83
A33: Feb | B33: 95
A34: Mar | B34: 164
A35: Apr | B35: 137
A36: May | B36: 121
A37: Jun | B37: 64
A38: Jul | B38: 169
A39: Aug | B39: 121
A40: Sep | B40: 143
A41: Oct | B41: 143
A42: Nov | B42: 67
A43: Dec | B43: 121
A44: 2022
A45: Jan | B45: 223
A46: Feb | B46: 283
A47: Mar | B47: 195
A48: Apr | B48: 242
...

Sheet Data
A1: OrderDate | B1: Region | C1: Country | D1: Um | E1: Customer | F1: Product ID | G1: Product | H1: Category | I1: Item | J1: Quantity | K1: Unit Cost | L1: Revenue | M1: Paid | N1: Buying Price | O1: Discount | P1: Selling Price | Q1: Sales Type
A2: 44567 | B2: East | C2: Japan | D2: Kg | E2: Jones | F2: P001 | G2: Product1 | H2: Category1 | I2: Pencil | J2: 95 | K2: 1.99 | L2: =K2*J2 -> 189.05 | M2: Online | N2: 24 | O2: 0 | P2: 45 | Q2: Wholesales
A3: 44584 | B3: Central | C3: USA | D3: Lt | E3: Kivell | F3: P002 | G3: Product2 | H3: Category2 | I3: Binder | J3: 50 | K3: 19.99 | L3: =K3*J3 -> 999.5 | M3: Cash | N3: 43 | O3: 0 | P3: 90 | Q3: Direct Sales
A4: 44601 | B4: Central | C4: France | D4: Ft | E4: Jardine | F4: P003 | G4: Product3 | H4: Category3 | I4: Biro | J4: 36 | K4: 4.99 | L4: =K4*J4 -> 179.64 | M4: Cash | N4: 32 | O4: 0 | P4: 74 | Q4: Direct Sales
A5: 44618 | B5: Central | C5: Germany | D5: No | E5: Gill | F5: P004 | G5: Product4 | H5: Category4 | I5: Pen | J5: 27 | K5: 19.99 | L5: =K5*J5 -> 539.73 | M5: Online | N5: 18 | O5: 0 | P5: 75 | Q5: Direct Sales
A6: 44635 | B6: West | C6: USA | D6: Kg | E6: Sorvino | F6: P005 | G6: Product5 | H6: Category5 | I6: Pencil | J6: 56 | K6: 2.99 | L6: =K6*J6 -> 167.44 | M6: Cash | N6: 27 | O6: 0 | P6: 62 | Q6: Online Sales
A7: 44652 | B7: East | C7: Japan | D7: Kg | E7: Jones | F7: P006 | G7: Product6 | H7: Category1 | I7: Binder | J7: 60 | K7: 4.99 | L7: =K7*J7 -> 299.4 | M7: Cash | N7: 46 | O7: 0 | P7: 58 | Q7: Wholesales
A8: 44669 | B8: Central | C8: Greece | D8: Lt | E8: Andrews | F8: P007 | G8: Product7 | H8: Category1 | I8: Blanco | J8: 75 | K8: 1.99 | L8: =K8*J8 -> 149.25 | M8: Online | N8: 46 | O8: 0 | P8: 63 | Q8: Direct Sales
A9: 44686 | B9: Central | C9: France | D9: Ft | E9: Jardine | F9: P008 | G9: Product8 | H9: Category2 | I9: Pencil | J9: 90 | K9: 4.99 | L9: =K9*J9 -> 449.1 | M9: Online | N9: 44 | O9: 0 | P9: 64 | Q9: Direct Sales
A10: 44703 | B10: West | C10: Greece | D10: No | E10: Thompson | F10: P009 | G10: Product9 | H10: Category3 | I10: Blanco | J10: 32 | K10: 1.99 | L10: =K10*J10 -> 63.68 | M10: Cash | N10: 30 | O10: 0 | P10: 82 | Q10: Online Sales
A11: 44720 | B11: East | C11: China | D11: Kg | E11: Jones | F11: P010 | G11: Product10 | H11: Category4 | I11: Binder | J11: 60 | K11: 8.99 | L11: =K11*J11 -> 539.4 | M11: Online | N11: 37 | O11: 0 | P11: 87 | Q11: Wholesales
A12: 44737 | B12: Central | C12: Germany | D12: Lt | E12: Morgan | F12: P011 | G12: Product11 | H12: Category5 | I12: Pencil | J12: 90 | K12: 4.99 | L12: =K12*J12 -> 449.1 | M12: Cash | N12: 39 | O12: 0 | P12: 58 | Q12: Direct Sales
A13: 44754 | B13: East | C13: Hong Kong | D13: Ft | E13: Howard | F13: P012 | G13: Product12 | H13: Category1 | I13: Paper | J13: 29 | K13: 1.99 | L13: =K13*J13 -> 57.71 | M13: Cash | N13: 11 | O13: 0 | P13: 63 | Q13: Wholesales
... A65: 44916 | B65: Central | C65: USA | D65: Lt | E65: Morgan | F65: P064 | G65: Product64 | H65: Category3 | I65: Highlighter | J65: 90 | K65: 4.99 | L65: =K65*J65 -> 449.1 | M65: Online | N65: 40 | O65: 0 | P65: 83 | Q65: Direct Sales
M1048576: Online

Sheet Sheet1
A1: Country | B1: Customer | C1: Item | D1: Quantity | E1: Unit Cost | F1: Revenue | I1: Product Satisfaction | J1: Rate
A2: Japan | B2: Jones | C2: Pencil | D2: 95 | E2: 1.99 | F2: =E2*D2 -> 189.05 | I2: Shipment (60%) | J2: 0.6 | L2: Item | M2: Amount
A3: USA | B3: Kivell | C3: Binder | D3: 50 | E3: 19.99 | F3: =E3*D3 -> 999.5 | I3: Quality (90%) | J3: 0.9 | L3: Pencil | M3: 75
A4: France | B4: Jardine | C4: Biro | D4: 36 | E4: 4.99 | F4: =E4*D4 -> 179.64 | I4: Ontime (95%) | J4: 0.95 | L4: Binder | M4: 62
A5: Germany | B5: Gill | C5: Pen | D5: 27 | E5: 19.99 | F5: =E5*D5 -> 539.73 | I5: Service (50%) | J5: 0.5 | L5: Biro | M5: 58
A6: USA | B6: Sorvino | C6: Pencil | D6: 56 | E6: 2.99 | F6: =E6*D6 -> 167.44 | I6: Accurate(93%) | J6: 0.93 | L6: Pen | M6: 63
A7: Japan | B7: Jones | C7: Binder | D7: 60 | E7: 4.99 | F7: =E7*D7 -> 299.4
A8: Greece | B8: Andrews | C8: Blanco | D8: 75 | E8: 1.99 | F8: =E8*D8 -> 149.25 | I8: Revenue | J8: Amount
A9: France | B9: Jardine | C9: Pencil | D9: 90 | E9: 4.99 | F9: =E9*D9 -> 449.1 | I9: Actual | J9: 545 | L9: Customers | M9: Revenue
A10: Greece | B10: Thompson | C10: Blanco | D10: 32 | E10: 1.99 | F10: =E10*D10 -> 63.68 | I10: Real | J10: 690 | L10: Jones | M10: 195
I11: Remark | J11: 59 | L11: Kivell | M11: 150
I12: Complete | J12: 775 | L12: Jardine | M12: 236
L13: Gill | M13: 227
L14: Sorvino | M14: 156
I15: Sales by Quantity | J15: by Quantity
I16: Germany | J16: 950 | L16: Year by figute | M16: 2021 | N16: 2022
I17: USA | J17: 560 | L17: Jan | M17: 189.05 | N17: 161.19
I18: Japan | J18: 376 | L18: Feb | M18: 199.5 | N18: 174.65
I19: Greece | J19: 627 | L19: Mar | M19: 179.64 | N19: 200.55
I20: France | J20: 556 | L20: Apr | M20: 159.73 | N20: 205.84
I21: Greece | J21: 760 | L21: May | M21: 167.44 | N21: 251.72
L22: Jun | M22: 209.4 | N22: 17.36
L23: Jul | M23: 149.25 | N23: 299.85
L24: Aug | M24: 149.1 | N24: 149.04
L25: Sep | M25: 63.68 | N25: 86.43
L26: Oct | M26: 156.4 | N26: 183.26
L27: Nov | M27: 149.1 | N27: 143.54
L28: Dec | M28: 157.71 | N28: 130.15

Sheet Sheet2

Sheet Pivot
A1: Country | B1: (All)
A3: Row Labels | B3: Sum of Quantity | C3: Sum of Revenue
A4: Binder | B4: 820 | C4: 9332.57
A5: Desk | B5: 166 | C5: 2478.44
A6: Pen | B6: 466 | C6: 4450.71
A7: Pen Set | B7: 367 | C7: 4405.2
A8: Pencil | B8: 584 | C8: 2972.58
A9: Blanco | B9: 258 | C9: 917.62
A10: Paper | B10: 261 | C10: 2862.39
A11: Highlighter | B11: 385 | C11: 1475.25
A12: Grand Total | B12: 3307 | C12: 28894.76

Sheet AdvFilter
A1: Country | B1: Paid | D1: Country | E1: Country | F1: Country

Sheet Tables
A1: Region | B1: 2021 | C1: 2022
A2: Northeast | B2: 50000 | C2: 80000
A3: Southeast | B3: 150000 | C3: 160000
A4: Midwest | B4: 250000 | C4: 150000
A5: Northwest | B5: 200000 | C5: 130000
A6: Southwest | B6: 90000 | C6: 140000
